{
 "cells": [
  {
   "cell_type": "code",
   "execution_count": 1,
   "id": "24e88aa7-636b-4a16-83e0-635427c671e5",
   "metadata": {},
   "outputs": [
    {
     "name": "stdout",
     "output_type": "stream",
     "text": [
      "Requirement already satisfied: ipython-sql in /home/flopezp/anaconda3/lib/python3.12/site-packages (0.5.0)\n",
      "Requirement already satisfied: prettytable in /home/flopezp/anaconda3/lib/python3.12/site-packages (from ipython-sql) (3.12.0)\n",
      "Requirement already satisfied: ipython in /home/flopezp/anaconda3/lib/python3.12/site-packages (from ipython-sql) (8.27.0)\n",
      "Requirement already satisfied: sqlalchemy>=2.0 in /home/flopezp/anaconda3/lib/python3.12/site-packages (from ipython-sql) (2.0.34)\n",
      "Requirement already satisfied: sqlparse in /home/flopezp/anaconda3/lib/python3.12/site-packages (from ipython-sql) (0.5.1)\n",
      "Requirement already satisfied: six in /home/flopezp/anaconda3/lib/python3.12/site-packages (from ipython-sql) (1.16.0)\n",
      "Requirement already satisfied: ipython-genutils in /home/flopezp/anaconda3/lib/python3.12/site-packages (from ipython-sql) (0.2.0)\n",
      "Requirement already satisfied: typing-extensions>=4.6.0 in /home/flopezp/anaconda3/lib/python3.12/site-packages (from sqlalchemy>=2.0->ipython-sql) (4.11.0)\n",
      "Requirement already satisfied: greenlet!=0.4.17 in /home/flopezp/anaconda3/lib/python3.12/site-packages (from sqlalchemy>=2.0->ipython-sql) (3.0.1)\n",
      "Requirement already satisfied: decorator in /home/flopezp/anaconda3/lib/python3.12/site-packages (from ipython->ipython-sql) (5.1.1)\n",
      "Requirement already satisfied: jedi>=0.16 in /home/flopezp/anaconda3/lib/python3.12/site-packages (from ipython->ipython-sql) (0.19.1)\n",
      "Requirement already satisfied: matplotlib-inline in /home/flopezp/anaconda3/lib/python3.12/site-packages (from ipython->ipython-sql) (0.1.6)\n",
      "Requirement already satisfied: prompt-toolkit<3.1.0,>=3.0.41 in /home/flopezp/anaconda3/lib/python3.12/site-packages (from ipython->ipython-sql) (3.0.43)\n",
      "Requirement already satisfied: pygments>=2.4.0 in /home/flopezp/anaconda3/lib/python3.12/site-packages (from ipython->ipython-sql) (2.15.1)\n",
      "Requirement already satisfied: stack-data in /home/flopezp/anaconda3/lib/python3.12/site-packages (from ipython->ipython-sql) (0.2.0)\n",
      "Requirement already satisfied: traitlets>=5.13.0 in /home/flopezp/anaconda3/lib/python3.12/site-packages (from ipython->ipython-sql) (5.14.3)\n",
      "Requirement already satisfied: pexpect>4.3 in /home/flopezp/anaconda3/lib/python3.12/site-packages (from ipython->ipython-sql) (4.8.0)\n",
      "Requirement already satisfied: wcwidth in /home/flopezp/anaconda3/lib/python3.12/site-packages (from prettytable->ipython-sql) (0.2.5)\n",
      "Requirement already satisfied: parso<0.9.0,>=0.8.3 in /home/flopezp/anaconda3/lib/python3.12/site-packages (from jedi>=0.16->ipython->ipython-sql) (0.8.3)\n",
      "Requirement already satisfied: ptyprocess>=0.5 in /home/flopezp/anaconda3/lib/python3.12/site-packages (from pexpect>4.3->ipython->ipython-sql) (0.7.0)\n",
      "Requirement already satisfied: executing in /home/flopezp/anaconda3/lib/python3.12/site-packages (from stack-data->ipython->ipython-sql) (0.8.3)\n",
      "Requirement already satisfied: asttokens in /home/flopezp/anaconda3/lib/python3.12/site-packages (from stack-data->ipython->ipython-sql) (2.0.5)\n",
      "Requirement already satisfied: pure-eval in /home/flopezp/anaconda3/lib/python3.12/site-packages (from stack-data->ipython->ipython-sql) (0.2.2)\n"
     ]
    }
   ],
   "source": [
    "!pip install ipython-sql"
   ]
  },
  {
   "cell_type": "code",
   "execution_count": 3,
   "id": "7f3a638c-53ce-4da9-88fb-d521d5239096",
   "metadata": {},
   "outputs": [],
   "source": [
    "import numpy as np\n",
    "import pandas as pd\n",
    "import sqlite3"
   ]
  },
  {
   "cell_type": "code",
   "execution_count": 5,
   "id": "c8a88cb0-6e88-438d-bac6-996883ba9c55",
   "metadata": {},
   "outputs": [],
   "source": [
    "%load_ext sql"
   ]
  },
  {
   "cell_type": "code",
   "execution_count": 7,
   "id": "d1ff69ca-5099-48b4-9879-b195c5549d7f",
   "metadata": {},
   "outputs": [],
   "source": [
    "import kagglehub\n",
    "hugomathien_soccer_path = kagglehub.dataset_download('hugomathien/soccer')"
   ]
  },
  {
   "cell_type": "code",
   "execution_count": 11,
   "id": "96ad2214-b3c5-4c64-ba1a-53db7bed6f3c",
   "metadata": {},
   "outputs": [
    {
     "name": "stdout",
     "output_type": "stream",
     "text": [
      "Traceback (most recent call last):\n",
      "  File \"/home/flopezp/anaconda3/lib/python3.12/site-packages/sqlalchemy/engine/base.py\", line 146, in __init__\n",
      "    self._dbapi_connection = engine.raw_connection()\n",
      "                             ^^^^^^^^^^^^^^^^^^^^^^^\n",
      "  File \"/home/flopezp/anaconda3/lib/python3.12/site-packages/sqlalchemy/engine/base.py\", line 3302, in raw_connection\n",
      "    return self.pool.connect()\n",
      "           ^^^^^^^^^^^^^^^^^^^\n",
      "  File \"/home/flopezp/anaconda3/lib/python3.12/site-packages/sqlalchemy/pool/base.py\", line 449, in connect\n",
      "    return _ConnectionFairy._checkout(self)\n",
      "           ^^^^^^^^^^^^^^^^^^^^^^^^^^^^^^^^\n",
      "  File \"/home/flopezp/anaconda3/lib/python3.12/site-packages/sqlalchemy/pool/base.py\", line 1263, in _checkout\n",
      "    fairy = _ConnectionRecord.checkout(pool)\n",
      "            ^^^^^^^^^^^^^^^^^^^^^^^^^^^^^^^^\n",
      "  File \"/home/flopezp/anaconda3/lib/python3.12/site-packages/sqlalchemy/pool/base.py\", line 712, in checkout\n",
      "    rec = pool._do_get()\n",
      "          ^^^^^^^^^^^^^^\n",
      "  File \"/home/flopezp/anaconda3/lib/python3.12/site-packages/sqlalchemy/pool/impl.py\", line 179, in _do_get\n",
      "    with util.safe_reraise():\n",
      "  File \"/home/flopezp/anaconda3/lib/python3.12/site-packages/sqlalchemy/util/langhelpers.py\", line 146, in __exit__\n",
      "    raise exc_value.with_traceback(exc_tb)\n",
      "  File \"/home/flopezp/anaconda3/lib/python3.12/site-packages/sqlalchemy/pool/impl.py\", line 177, in _do_get\n",
      "    return self._create_connection()\n",
      "           ^^^^^^^^^^^^^^^^^^^^^^^^^\n",
      "  File \"/home/flopezp/anaconda3/lib/python3.12/site-packages/sqlalchemy/pool/base.py\", line 390, in _create_connection\n",
      "    return _ConnectionRecord(self)\n",
      "           ^^^^^^^^^^^^^^^^^^^^^^^\n",
      "  File \"/home/flopezp/anaconda3/lib/python3.12/site-packages/sqlalchemy/pool/base.py\", line 674, in __init__\n",
      "    self.__connect()\n",
      "  File \"/home/flopezp/anaconda3/lib/python3.12/site-packages/sqlalchemy/pool/base.py\", line 900, in __connect\n",
      "    with util.safe_reraise():\n",
      "  File \"/home/flopezp/anaconda3/lib/python3.12/site-packages/sqlalchemy/util/langhelpers.py\", line 146, in __exit__\n",
      "    raise exc_value.with_traceback(exc_tb)\n",
      "  File \"/home/flopezp/anaconda3/lib/python3.12/site-packages/sqlalchemy/pool/base.py\", line 896, in __connect\n",
      "    self.dbapi_connection = connection = pool._invoke_creator(self)\n",
      "                                         ^^^^^^^^^^^^^^^^^^^^^^^^^^\n",
      "  File \"/home/flopezp/anaconda3/lib/python3.12/site-packages/sqlalchemy/engine/create.py\", line 643, in connect\n",
      "    return dialect.connect(*cargs, **cparams)\n",
      "           ^^^^^^^^^^^^^^^^^^^^^^^^^^^^^^^^^^\n",
      "  File \"/home/flopezp/anaconda3/lib/python3.12/site-packages/sqlalchemy/engine/default.py\", line 621, in connect\n",
      "    return self.loaded_dbapi.connect(*cargs, **cparams)\n",
      "           ^^^^^^^^^^^^^^^^^^^^^^^^^^^^^^^^^^^^^^^^^^^^\n",
      "sqlite3.OperationalError: unable to open database file\n",
      "\n",
      "The above exception was the direct cause of the following exception:\n",
      "\n",
      "Traceback (most recent call last):\n",
      "  File \"/home/flopezp/anaconda3/lib/python3.12/site-packages/sql/magic.py\", line 196, in execute\n",
      "    conn = sql.connection.Connection.set(\n",
      "           ^^^^^^^^^^^^^^^^^^^^^^^^^^^^^^\n",
      "  File \"/home/flopezp/anaconda3/lib/python3.12/site-packages/sql/connection.py\", line 70, in set\n",
      "    cls.current = existing or Connection(descriptor, connect_args, creator)\n",
      "                              ^^^^^^^^^^^^^^^^^^^^^^^^^^^^^^^^^^^^^^^^^^^^^\n",
      "  File \"/home/flopezp/anaconda3/lib/python3.12/site-packages/sql/connection.py\", line 55, in __init__\n",
      "    self.internal_connection = engine.connect()\n",
      "                               ^^^^^^^^^^^^^^^^\n",
      "  File \"/home/flopezp/anaconda3/lib/python3.12/site-packages/sqlalchemy/engine/base.py\", line 3278, in connect\n",
      "    return self._connection_cls(self)\n",
      "           ^^^^^^^^^^^^^^^^^^^^^^^^^^\n",
      "  File \"/home/flopezp/anaconda3/lib/python3.12/site-packages/sqlalchemy/engine/base.py\", line 148, in __init__\n",
      "    Connection._handle_dbapi_exception_noconnection(\n",
      "  File \"/home/flopezp/anaconda3/lib/python3.12/site-packages/sqlalchemy/engine/base.py\", line 2442, in _handle_dbapi_exception_noconnection\n",
      "    raise sqlalchemy_exception.with_traceback(exc_info[2]) from e\n",
      "  File \"/home/flopezp/anaconda3/lib/python3.12/site-packages/sqlalchemy/engine/base.py\", line 146, in __init__\n",
      "    self._dbapi_connection = engine.raw_connection()\n",
      "                             ^^^^^^^^^^^^^^^^^^^^^^^\n",
      "  File \"/home/flopezp/anaconda3/lib/python3.12/site-packages/sqlalchemy/engine/base.py\", line 3302, in raw_connection\n",
      "    return self.pool.connect()\n",
      "           ^^^^^^^^^^^^^^^^^^^\n",
      "  File \"/home/flopezp/anaconda3/lib/python3.12/site-packages/sqlalchemy/pool/base.py\", line 449, in connect\n",
      "    return _ConnectionFairy._checkout(self)\n",
      "           ^^^^^^^^^^^^^^^^^^^^^^^^^^^^^^^^\n",
      "  File \"/home/flopezp/anaconda3/lib/python3.12/site-packages/sqlalchemy/pool/base.py\", line 1263, in _checkout\n",
      "    fairy = _ConnectionRecord.checkout(pool)\n",
      "            ^^^^^^^^^^^^^^^^^^^^^^^^^^^^^^^^\n",
      "  File \"/home/flopezp/anaconda3/lib/python3.12/site-packages/sqlalchemy/pool/base.py\", line 712, in checkout\n",
      "    rec = pool._do_get()\n",
      "          ^^^^^^^^^^^^^^\n",
      "  File \"/home/flopezp/anaconda3/lib/python3.12/site-packages/sqlalchemy/pool/impl.py\", line 179, in _do_get\n",
      "    with util.safe_reraise():\n",
      "  File \"/home/flopezp/anaconda3/lib/python3.12/site-packages/sqlalchemy/util/langhelpers.py\", line 146, in __exit__\n",
      "    raise exc_value.with_traceback(exc_tb)\n",
      "  File \"/home/flopezp/anaconda3/lib/python3.12/site-packages/sqlalchemy/pool/impl.py\", line 177, in _do_get\n",
      "    return self._create_connection()\n",
      "           ^^^^^^^^^^^^^^^^^^^^^^^^^\n",
      "  File \"/home/flopezp/anaconda3/lib/python3.12/site-packages/sqlalchemy/pool/base.py\", line 390, in _create_connection\n",
      "    return _ConnectionRecord(self)\n",
      "           ^^^^^^^^^^^^^^^^^^^^^^^\n",
      "  File \"/home/flopezp/anaconda3/lib/python3.12/site-packages/sqlalchemy/pool/base.py\", line 674, in __init__\n",
      "    self.__connect()\n",
      "  File \"/home/flopezp/anaconda3/lib/python3.12/site-packages/sqlalchemy/pool/base.py\", line 900, in __connect\n",
      "    with util.safe_reraise():\n",
      "  File \"/home/flopezp/anaconda3/lib/python3.12/site-packages/sqlalchemy/util/langhelpers.py\", line 146, in __exit__\n",
      "    raise exc_value.with_traceback(exc_tb)\n",
      "  File \"/home/flopezp/anaconda3/lib/python3.12/site-packages/sqlalchemy/pool/base.py\", line 896, in __connect\n",
      "    self.dbapi_connection = connection = pool._invoke_creator(self)\n",
      "                                         ^^^^^^^^^^^^^^^^^^^^^^^^^^\n",
      "  File \"/home/flopezp/anaconda3/lib/python3.12/site-packages/sqlalchemy/engine/create.py\", line 643, in connect\n",
      "    return dialect.connect(*cargs, **cparams)\n",
      "           ^^^^^^^^^^^^^^^^^^^^^^^^^^^^^^^^^^\n",
      "  File \"/home/flopezp/anaconda3/lib/python3.12/site-packages/sqlalchemy/engine/default.py\", line 621, in connect\n",
      "    return self.loaded_dbapi.connect(*cargs, **cparams)\n",
      "           ^^^^^^^^^^^^^^^^^^^^^^^^^^^^^^^^^^^^^^^^^^^^\n",
      "sqlalchemy.exc.OperationalError: (sqlite3.OperationalError) unable to open database file\n",
      "(Background on this error at: https://sqlalche.me/e/20/e3q8)\n",
      "\n",
      "Connection info needed in SQLAlchemy format, example:\n",
      "               postgresql://username:password@hostname/dbname\n",
      "               or an existing connection: dict_keys([])\n"
     ]
    }
   ],
   "source": [
    "%sql sqlite:////kaggle/input/soccer/database.sqlite"
   ]
  }
 ],
 "metadata": {
  "kernelspec": {
   "display_name": "Python 3 (ipykernel)",
   "language": "python",
   "name": "python3"
  },
  "language_info": {
   "codemirror_mode": {
    "name": "ipython",
    "version": 3
   },
   "file_extension": ".py",
   "mimetype": "text/x-python",
   "name": "python",
   "nbconvert_exporter": "python",
   "pygments_lexer": "ipython3",
   "version": "3.12.7"
  }
 },
 "nbformat": 4,
 "nbformat_minor": 5
}
